Python code to be executed: 
>>>import sys

def set_value(x):
    global buf
    buf = x

def get_value():
    global buf
    return buf

def print_global_map():
    print 'Printing some_global_map within Python:', some_global_map
    sys.stdout.flush()
<<<
Setting the string:   'This string should survive within the Python environment'
Read back the string: 'This string should survive within the Python environment'
Trying to read back from second snippet:
Caught Python Exception: 'NameError
Python 2.X.Y: /path/python


A problem occurred in a Python script.  Here is the sequence of
function calls leading up to the error, in the order they occurred.

 <string> in get_value()

NameError: global name 'buf' is not defined
    __class__ = NameError
    __delattr__ = <method-wrapper '__delattr__' of exceptions.NameError object at 0x[memory_address]>
    __dict__ = {}
        message = "global name 'buf' is not defined"

The above is a description of an error in a Python program.  Here is
the original traceback:

Traceback (most recent call last):
  File "<string>", line 12, in get_value
NameError: global name 'buf' is not defined

Error while calling function 'get_value' with no params.'
Associated 'some_global_map' with: {Oui: 16, bon: 512, est: 64, et: 256, il: 32, juste: 128}
Read back from Python environment: {Oui: 16, bon: 512, est: 64, et: 256, il: 32, juste: 128}
Printing some_global_map within Python: {'Oui': 16, 'est': 64, 'juste': 128, 'il': 32, 'bon': 512, 'et': 256}
Dump of the 'python_other' compiled environment
